Workbook

Sheet Information
B2: INFORMATION
B4: COMPANY INFO | E4: NOTES
B5: Company Name | C5: Microsoft Corporation
B6: Ticker | C6: MSFT
B7: Fiscal Year (Year 0, most recent actual) | C7: FY2026, ended June 30
B8: Valuation Date | C8: June 30, 2026 | E8: Valuation date set as fiscal year end to align with cash flow periods and discounting periods
B9: Date of Model Preparation | C9: August 3, 2026 | E9: All inputs reflect the most recently available information as of model preparation, August 2026.
B11: LEGEND
B12: Historical Value (from specific year's 10-K) | C12: XXX
B13: Value taken from 3rd party source | C13: XXX
B14: Projected Value | C14: XXX
B15: Projected Value (Hardcoded) | C15: XXX
B17: This model was prepared by Lee Yi Rui.

Sheet Projections
B2: REVENUE AND 5 - YEAR PROJECTION
C4: Actual | D4: Actual | E4: Actual | F4: Actual | G4: Forecast | H4: Forecast | I4: Forecast | J4: Forecast | K4: Forecast
B5: ($mm) | C5: FY23 | D5: FY24 | E5: FY25 | F5: FY26 | G5: FY27 | H5: FY28 | I5: FY29 | J5: FY30 | K5: FY31
B6: Revenue | C6: 211915 | D6: 245122 | E6: 281724 | F6: 331839 | G6: =F6*(1+G17) -> 391570.02 | H6: =G6*(1+H17) -> 450305.52 | I6: =H6*(1+I17) -> 506593.71 | J6: =I6*(1+J17) -> 559786.05 | K6: =J6*(1+K17) -> 610166.8
B7: Less: Cost of revenue | C7: -65863 | D7: -74114 | E7: -87831 | F7: -106374 | G7: =-G18*G6 -> -127260.26 | H7: =-H18*H6 -> -148150.52 | I7: =-I18*I6 -> -168189.11 | J7: =-J18*J6 -> -186968.54 | K7: =-K18*K6 -> -205016.04
B8: Gross Margin | C8: =C6+C7 -> 146052 | D8: =D6+D7 -> 171008 | E8: =E6+E7 -> 193893 | F8: =F6+F7 -> 225465 | G8: =G6+G7 -> 264309.76 | H8: =H6+H7 -> 302155.01 | I8: =I6+I7 -> 338404.6 | J8: =J6+J7 -> 372817.51 | K8: =K6+K7 -> 405150.75
B9: Less:
B10: Research and Development | C10: 27195 | D10: 29510 | E10: 32488 | F10: 35562 | G10: =G19*G6 -> 40331.712 | H10: =H19*H6 -> 45030.552 | I10: =I19*I6 -> 49646.184 | J10: =J19*J6 -> 53739.461 | K10: =K19*K6 -> 57355.679
B11: Sales and Marketing | C11: 22759 | D11: 24456 | E11: 25654 | F11: 26710 | G11: =F11*(1+G20) -> 27805.11 | H11: =G11*(1+H20) -> 28917.314 | I11: =H11*(1+I20) -> 29761.7 | J11: =I11*(1+J20) -> 30600.98 | K11: =J11*(1+K20) -> 31463.928
B12: General and Administrative | C12: 7575 | D12: 7609 | E12: 7223 | F12: 7956 | G12: =F12*(1+G21) -> 8210.592 | H12: =G12*(1+H21) -> 8473.3309 | I12: =H12*(1+I21) -> 8661.4389 | J12: =I12*(1+J21) -> 8853.7228 | K12: =J12*(1+K21) -> 9050.2755
B13: Total Expenses | C13: =-SUM(C10:C12) -> -57529 | D13: =-SUM(D10:D12) -> -61575 | E13: =-SUM(E10:E12) -> -65365 | F13: =-SUM(F10:F12) -> -70228 | G13: =-SUM(G10:G12) -> -76347.414 | H13: =-SUM(H10:H12) -> -82421.198 | I13: =-SUM(I10:I12) -> -88069.323 | J13: =-SUM(J10:J12) -> -93194.164 | K13: =-SUM(K10:K12) -> -97869.882
B14: Operating profit | C14: =C8+C13 -> 88523 | D14: =D8+D13 -> 109433 | E14: =E8+E13 -> 128528 | F14: =F8+F13 -> 155237 | G14: =G8+G13 -> 187962.35 | H14: =H8+H13 -> 219733.81 | I14: =I8+I13 -> 250335.28 | J14: =J8+J13 -> 279623.35 | K14: =K8+K13 -> 307280.87
B16: ITEM | C16: FY23 | D16: FY24 | E16: FY25 | F16: FY26 | G16: FY27 | H16: FY28 | I16: FY29 | J16: FY30 | K16: FY31 | L16: ASSUMPTIONS
B17: Revenue (Dollar Growth Rate%, ↑ in 2027 but ↓ trend FY28 onwards) | C17: N/A | D17: =(D6-C6)/C6 -> 0.15669962 | E17: =(E6-D6)/D6 -> 0.14932156 | F17: =(F6-E6)/E6 -> 0.17788687 | G17: 0.18 | H17: 0.15 | I17: 0.125 | J17: 0.105 | K17: 0.09 | L17: - Company guidance, Microsoft reports revenue increased 18% to 90b in Q1 FY27. - FY28 onwards: Blended growth rate likely to decrease; Azure growth arises from limited supply, hence growth should normalise when capacity constraints ease.
B18: Cost of Revenue (% of Revenue, ↑Trend) | C18: =-C7/C6 -> 0.31079914 | D18: =-D7/D6 -> 0.30235556 | E18: =-E7/E6 -> 0.31176258 | F18: =-F7/F6 -> 0.32055907 | G18: 0.325 | H18: 0.329 | I18: 0.332 | J18: 0.334 | K18: 0.336 | L18: - Microsoft Cloud gross margin decreased: FY26 Q3 Earnings - Gross margin% decrease driven by investments in AI infrastructure.
B19: Research and Development (% of Revenue, ↓Trend) | C19: =C10/C6 -> 0.12832975 | D19: =D10/D6 -> 0.12038903 | E19: =E10/E6 -> 0.11531854 | F19: =F10/F6 -> 0.10716643 | G19: 0.103 | H19: 0.1 | I19: 0.098 | J19: 0.096 | K19: 0.094 | L19: - Revenue outgrows R&D expense. - R&D will still increase due to Azure. - Floors at ~9% to 9.5% of Revenue.
B20: Sales and Marketing (Dollar Growth Rate%, ↓Trend) | C20: N/A | D20: =(D11-C11)/C11 -> 0.074563909 | E20: =(E11-D11)/D11 -> 0.048985934 | F20: =(F11-E11)/E11 -> 0.041163171 | G20: 0.041 | H20: 0.04 | I20: 0.0292 | J20: 0.0282 | K20: 0.0282 | L20: - Not proportionate to Revenue. - Scales and grows with inflation: - FY27 - FY28: IMF CPI inflation 3.2% CPI used for near-term as it reflects immediate shifts in price. - FY29 - FY31: PCE inflation 2.22% PCE used for long-term as it aligns with Federal Reserve's targets. - Added premium for wage growth, new product pushes, etc.
B21: General and Administrative (Dollar Growth Rate%, ↓ Trend) | C21: N/A | D21: =(D12-C12)/C12 -> 0.0044884488 | E21: =(E12-D12)/D12 -> -0.050729399 | F21: =(F12-E12)/E12 -> 0.10148138 | G21: 0.032 | H21: 0.032 | I21: 0.0222 | J21: 0.0222 | K21: 0.0222 | L21: - Not proportionate to Revenue. - FY23-26 growth were dominated by one-off items: 1. Employee severance in FY23. 2. Acquisition of Activision Blizzard offset in FY24 and rolled over in FY25. 3. Higher legal fees and gains on divestures from prior period impacted FY26. - Forecast uses inflation-linked growth instead as a cleaner baseline: - FY27 - FY28: IMF CPI inflation 3.2% CPI used for near-term as it reflects immediate shifts in price. - FY29 - FY31: PCE inflation 2.22% PCE used for long-term as it aligns with Federal Reserve's targets.

Sheet FCF
B2: FREE CASH FLOW
C4: Actual | D4: Forecast | E4: Forecast | F4: Forecast | G4: Forecast | H4: Forecast
B5: ($mm) | C5: FY26 | D5: FY27 | E5: FY28 | F5: FY29 | G5: FY30 | H5: FY31
B6: Revenue | C6: =Projections!F6 -> 331839 | D6: =Projections!G6 -> 391570.02 | E6: =Projections!H6 -> 450305.52 | F6: =Projections!I6 -> 506593.71 | G6: =Projections!J6 -> 559786.05 | H6: =Projections!K6 -> 610166.8
B7: Operating Profit | C7: =Projections!F14 -> 155237 | D7: =Projections!G14 -> 187962.35 | E7: =Projections!H14 -> 219733.81 | F7: =Projections!I14 -> 250335.28 | G7: =Projections!J14 -> 279623.35 | H7: =Projections!K14 -> 307280.87
B8: Less: Taxes | C8: =-E19 -> -30115.978 | D8: =-F19 -> -36840.62 | E8: =-G19 -> -43507.294 | F8: =-H19 -> -50067.056 | G8: =-I19 -> -56204.293 | H8: =-J19 -> -62070.736
B9: NOPAT | C9: =C7+C8 -> 125121.02 | D9: =D7+D8 -> 151121.73 | E9: =E7+E8 -> 176226.51 | F9: =F7+F8 -> 200268.22 | G9: =G7+G8 -> 223419.05 | H9: =H7+H8 -> 245210.14
B10: Add: Depreciation and Amortisation | C10: =E26 -> 38534 | D10: =F26 -> 52353.846 | E10: =G26 -> 72863.236 | F10: =H26 -> 92305.558 | G10: =I26 -> 111009.86 | H10: =J26 -> 128766.9
B11: Less: Capital Expenditure | C11: =-E47 -> -115948 | D11: =-F47 -> -175000 | E11: =-G47 -> -189128.32 | F11: =-H47 -> -204157.27 | G11: =-I47 -> -217196.99 | H11: =-J47 -> -230643.05
B12: Less / Add: Increase / Decrease in NWC | C12: =-E61 -> 6678 | D12: =-F61 -> 7098.05 | E12: =-G61 -> 8314.3575 | F12: =-H61 -> 7967.9259 | G12: =-I61 -> 7529.69 | H12: =-J61 -> 7131.6921
B13: Unlevered Free Cash Flow | C13: =C9+C10+C11+C12 -> 54385.022 | D13: =D9+D10+D11+D12 -> 35573.625 | E13: =E9+E10+E11+E12 -> 68275.789 | F13: =F9+F10+F11+F12 -> 96384.44 | G13: =G9+G10+G11+G12 -> 124761.61 | H13: =H9+H10+H11+H12 -> 150465.68
B15: TAXES AMOUNT AND % ASSUMPTIONS
B16: ($mm) | C16: FY24 | D16: FY25 | E16: FY26 | F16: FY27 | G16: FY28 | H16: FY29 | I16: FY30 | J16: FY31
B17: Operating Profit (Actual / Projected) | C17: =Projections!D14 -> 109433 | D17: =Projections!E14 -> 128528 | E17: =Projections!F14 -> 155237 | F17: =Projections!G14 -> 187962.35 | G17: =Projections!H14 -> 219733.81 | H17: =Projections!I14 -> 250335.28 | I17: =Projections!J14 -> 279623.35 | J17: =Projections!K14 -> 307280.87
B18: Effective Tax Rate (Actual / Projected) | C18: 0.182 | D18: 0.176 | E18: 0.194 | F18: 0.196 | G18: 0.198 | H18: 0.2 | I18: 0.201 | J18: 0.202
B19: Taxes (Operating Profit * effective tax rate) | C19: =C18*C17 -> 19916.806 | D19: =D18*D17 -> 22620.928 | E19: =E18*E17 -> 30115.978 | F19: =F17*F18 -> 36840.62 | G19: =G17*G18 -> 43507.294 | H19: =H17*H18 -> 50067.056 | I19: =I17*I18 -> 56204.293 | J19: =J17*J18 -> 62070.736
B20: Trend reverses in FY26 due to mix shift: U.S. income as % of total income increased from 56.0% in FY25 to 62.4% in FY26. Projected rate from FY27-31 will mildly incline towards U.S. federal statutory rate of 21% as more income is taxed in the U.S. (Computed taxes amount will not tie to reported taxes in FY26 10-K, as GAAP tax provision includes non-operating income)
B24: DEPRECIATION & AMORTISATION AMOUNT AND % ASSUMPTIONS
B25: ($mm) | C25: FY24 | D25: FY25 | E25: FY26 | F25: FY27 | G25: FY28 | H25: FY29 | I25: FY30 | J25: FY31
B26: Depreciation & amortisation expense (Actual / Projected) | C26: 20958 | D26: 29433 | E26: 38534 | F26: =D35 -> 52353.846 | G26: =D36 -> 72863.236 | H26: =D37 -> 92305.558 | I26: =D38 -> 111009.86 | J26: =D39 -> 128766.9
B27: Revenue (Actual / Projected) | C27: =Projections!$D$6 -> 245122 | D27: =Projections!$E$6 -> 281724 | E27: =Projections!$F$6 -> 331839 | F27: =Projections!$G$6 -> 391570.02 | G27: =Projections!$H$6 -> 450305.52 | H27: =Projections!$I$6 -> 506593.71 | I27: =Projections!$J$6 -> 559786.05 | J27: =Projections!$K$6 -> 610166.8
B28: Depreciation & amortisation expense / Revenue % | C28: =C26/C27 -> 0.085500281 | D28: =D26/D27 -> 0.10447459 | E28: =E26/E27 -> 0.11612258 | F28: =F26/F27 -> 0.13370239 | G28: =G26/G27 -> 0.16180844 | H28: =H26/H27 -> 0.18220826 | I28: =I26/I27 -> 0.19830765 | J28: =J26/J27 -> 0.21103558
B29: Increasing AI infrastructure investment and higher FY27 capex per company guidance suggests D&A will continue to rise in FY27. Trend mechanically follows capex since newly capitalised assets start depreciating going forward while compounding through future years. Refer to PPE rollforward for D&A calculations.
B33: PPE ROLLFORWARD (TYING D&A TO CAPEX) AND ASSUMPTIONS
B34: ($mm) | C34: Opening PPE | D34: D&A @5.98yrs | E34: CapEx | F34: Closing PPE
B35: FY27 | C35: 313076 | D35: =C35/5.98 -> 52353.846 | E35: =$F$47 -> 175000 | F35: =C35-D35+E35 -> 435722.15
B36: FY28 | C36: =F35 -> 435722.15 | D36: =C36/5.98 -> 72863.236 | E36: =$G$47 -> 189128.32 | F36: =C36-D36+E36 -> 551987.24
B37: FY29 | C37: =F36 -> 551987.24 | D37: =C37/5.98 -> 92305.558 | E37: =$H$47 -> 204157.27 | F37: =C37-D37+E37 -> 663838.95
B38: FY30 | C38: =F37 -> 663838.95 | D38: =C38/5.98 -> 111009.86 | E38: =$I$47 -> 217196.99 | F38: =C38-D38+E38 -> 770026.08
B39: FY31 | C39: =F38 -> 770026.08 | D39: =C39/5.98 -> 128766.9 | E39: =$J$47 -> 230643.05 | F39: =C39-D39+E39 -> 871902.22
B40: FY26 10-K: servers and network equipment estimated useful life = two to six years. Capex taken from assumptions below. Useful life assumed at $204,966 (FY26 Opening PPE) / $34,300 (FY26 D&A) = 5.98 years (2.d.p), falls within 2 - 6 years. Opening PPE for FY27 taken from closing FY26 10-K. D&A for projected year = Opening PPE / 5.98 years.
B45: CAPITAL EXPENDITURE AMOUNT AND % ASSUMPTIONS
B46: ($mm) | C46: FY24 | D46: FY25 | E46: FY26 | F46: FY27 | G46: FY28 | H46: FY29 | I46: FY30 | J46: FY31
B47: Capital expenditure (Actual / Projected) | C47: 44477 | D47: 64551 | E47: 115948 | F47: 175000 | G47: =G48*G49 -> 189128.32 | H47: =H48*H49 -> 204157.27 | I47: =I48*I49 -> 217196.99 | J47: =J48*J49 -> 230643.05
B48: Revenue (Actual / Projected) | C48: =Projections!$D$6 -> 245122 | D48: =Projections!$E$6 -> 281724 | E48: =Projections!$F$6 -> 331839 | F48: =Projections!$G$6 -> 391570.02 | G48: =Projections!$H$6 -> 450305.52 | H48: =Projections!$I$6 -> 506593.71 | I48: =Projections!$J$6 -> 559786.05 | J48: =Projections!$K$6 -> 610166.8
B49: Capital expenditure / Revenue % | C49: =C47/C48 -> 0.18144842 | D49: =D47/D48 -> 0.22912851 | E49: =E47/E48 -> 0.34941041 | F49: =F47/F48 -> 0.44691879 | G49: 0.42 | H49: 0.403 | I49: 0.388 | J49: 0.378
B50: Capex guidance per Microsoft: $175 billion for FY27. Subsequent years' growth expected to normalise once Azure/cloud capacity constrainst start easing. Hence FY27's growth rate from FY26 is inflated and not expected to continue (still increase but less magnitude) For FY28-31, capex rate as % of Revenue declines from FY27's rate, but not below 34.9% (increasing trend from FY24-26)
B54: CHANGE IN NET WORKING CAPITAL AND % ASSUMPTIONS
B55: ($mm) | C55: FY24 | D55: FY25 | E55: FY26 | F55: FY27 | G55: FY28 | H55: FY29 | I55: FY30 | J55: FY31
B56: Revenue (Actual / Projected) | C56: =Projections!$D$6 -> 245122 | D56: =Projections!$E$6 -> 281724 | E56: =Projections!$F$6 -> 331839 | F56: =Projections!$G$6 -> 391570.02 | G56: =Projections!$H$6 -> 450305.52 | H56: =Projections!$I$6 -> 506593.71 | I56: =Projections!$J$6 -> 559786.05 | J56: =Projections!$K$6 -> 610166.8
...

Sheet WACC
B2: WACC (WEIGHTED AVERAGE COST OF CAPITAL)
B4: CAPITAL STRUCTURE
B5: Item | C5: Long-Term Debt | D5: Finance Leases | E5: Ordinary Shares
B6: Number of Shares (As at June 30 2026) | E6: 7427000000 | F6: Taken from Balance Sheet
B7: Share Price as at June 30 2026 (Close) | E7: 373.02 | F7: Taken from Yahoo Finance
B8: Market Value (MV) of Capital Source (mm) | C8: 36500 | D8: 66594 | E8: =E7*E6/1000000 -> 2770419.5
B9: Weights | C9: =C8/SUM($C$8:$E$8) -> 0.01270222 | D9: =D8/SUM($C$8:$E$8) -> 0.023175113 | E9: =E8/SUM($C$8:$E$8) -> 0.96412267
B10: Operating lease liabilities excluded from calculation as they are not part of capital financing. MV of long-term debt taken as fair value and not accounting value of $40b
B14: COST OF EQUITY (CAPM METHOD)
B15: Rf, Risk-Free Rate (10yr Treasury, %) | C15: 0.04718 | D15: Current 10-year US Treasury yield
B16: β, Beta | C16: 1.13 | D16: 5yr monthly beta, Yahoo Finance
B17: (Rm - Rf), Equity Risk Premium (%) | C17: 0.0442 | D17: Aswath Damodaran's July 2026 List of Equity Risk Premiums, by country
B18: Cost of Equity, Re = Rf + β(Rm - Rf) | C18: =C15+C16*C17 -> 0.097126
B20: COST OF DEBT (LONG-TERM DEBT)
B21: Issuance | C21: Effective Interest Rate | D21: Effective Interest Rate (Midpoint) | E21: Debt as at June 30 2026 (face value, mm) | F21: Interest Expense on Debt (mm)
B22: 2009 issuance of $3.8 billion | C22: 0.0524 | D22: 0.0524 | E22: 520 | F22: =E22*D22 -> 27.248
B23: 2010 issuance of $4.8 billion | C23: 0.0457 | D23: 0.0457 | E23: 486 | F23: =E23*D23 -> 22.2102
B24: 2011 issuance of $2.3 billion | C24: 0.0536 | D24: 0.0536 | E24: 718 | F24: =E24*D24 -> 38.4848
B25: 2012 issuance of $2.3 billion | C25: 0.0357 | D25: 0.0357 | E25: 454 | F25: =E25*D25 -> 16.2078
B26: 2013 issuance of $5.2 billion | C26: 3.83%–4.92% | D26: =AVERAGE(VALUE(LEFT(C26, FIND("–", C26)-1)), VALUE(MID(C26, FIND("–", C26)+1, LEN(C26)))) -> 0.04375 | E26: 314 | F26: =E26*D26 -> 13.7375
B27: 2013 issuance of €4.1 billion | C27: 2.69%–3.22% | D27: =AVERAGE(VALUE(LEFT(C27, FIND("–", C27)-1)), VALUE(MID(C27, FIND("–", C27)+1, LEN(C27)))) -> 0.02955 | E27: 2630 | F27: =E27*D27 -> 77.7165
B28: 2015 issuance of $23.8 billion | C28: 3.60%–4.78% | D28: =AVERAGE(VALUE(LEFT(C28, FIND("–", C28)-1)), VALUE(MID(C28, FIND("–", C28)+1, LEN(C28)))) -> 0.0419 | E28: 4555 | F28: =E28*D28 -> 190.8545
B29: 2016 issuance of $19.8 billion | C29: 2.46%–4.03% | D29: =AVERAGE(VALUE(LEFT(C29, FIND("–", C29)-1)), VALUE(MID(C29, FIND("–", C29)+1, LEN(C29)))) -> 0.03245 | E29: 7930 | F29: =E29*D29 -> 257.3285
B30: 2017 issuance of $17.1 billion | C30: 3.38%–5.49% | D30: =AVERAGE(VALUE(LEFT(C30, FIND("–", C30)-1)), VALUE(MID(C30, FIND("–", C30)+1, LEN(C30)))) -> 0.04435 | E30: 6833 | F30: =E30*D30 -> 303.04355
B31: 2020 issuance of $10.1 billion | C31: 2.53%–5.43% | D31: =AVERAGE(VALUE(LEFT(C31, FIND("–", C31)-1)), VALUE(MID(C31, FIND("–", C31)+1, LEN(C31)))) -> 0.0398 | E31: 10111 | F31: =E31*D31 -> 402.4178
B32: 2021 issuance of $8.2 billion | C32: 2.92%–3.04% | D32: =AVERAGE(VALUE(LEFT(C32, FIND("–", C32)-1)), VALUE(MID(C32, FIND("–", C32)+1, LEN(C32)))) -> 0.0298 | E32: 8185 | F32: =E32*D32 -> 243.913
B33: 2023 issuance of $0.1 billion | C33: 5.16%–5.49% | D33: =AVERAGE(VALUE(LEFT(C33, FIND("–", C33)-1)), VALUE(MID(C33, FIND("–", C33)+1, LEN(C33)))) -> 0.05325 | E33: 56 | F33: =E33*D33 -> 2.982
B34: 2024 issuance of $3.3 billion | C34: 5.16%–5.49% | D34: =AVERAGE(VALUE(LEFT(C34, FIND("–", C34)-1)), VALUE(MID(C34, FIND("–", C34)+1, LEN(C34)))) -> 0.05325 | E34: 3344 | F34: =E34*D34 -> 178.068
B35: Total | E35: =SUM(E22:E34) -> 46136 | F35: =SUM(F22:F34) -> 1774.2122
B37: Cost of Debt, Rd (Blended, %) | C37: =F35/E35 -> 0.038456133
B38: Tax Rate | C38: 0.21 | D38: U.S. federal statutory rate; tax savings should be calculated at the marginal rate
B39: After-Tax Cost of Debt, AT Rd = Rd * (1 - Tax Rate) | C39: =C37*(1-C38) -> 0.030380345
B40: Effective interest rates for 2013 to 2024 issuances were given as a range of rates; Midpoint of the range of interest rates were used in the calculation of interest on debt.
B44: COST OF DEBT (FINANCIAL LEASES)
B45: Pre-Tax Cost of Debt | C45: 0.045 | D45: Given in Note 13 of FY26 10-K
B46: Tax Rate | C46: 0.21 | D46: U.S. federal statutory rate; tax savings should be calculated at the marginal rate
B47: After-Tax Cost of Debt | C47: =C45*(1-C46) -> 0.03555
B49: WACC CALCULATION
B50: Items | C50: Long-Term Debt | D50: Financial Leases | E50: Ordinary Shares
B51: Weight (Wd, We) | C51: =C9 -> 0.01270222 | D51: =D9 -> 0.023175113 | E51: =E9 -> 0.96412267
...

Sheet DCF Valuation
B2: DCF VALUATION
B5: ($mm) | C5: FY27 | D5: FY28 | E5: FY29 | F5: FY30 | G5: FY31
B6: Unlevered FCF | C6: =FCF!D13 -> 35573.625 | D6: =FCF!E13 -> 68275.789 | E6: =FCF!F13 -> 96384.44 | F6: =FCF!G13 -> 124761.61 | G6: =FCF!H13 -> 150465.68 | H6: Linked from 'FCF Build'
B7: Discount Factor | C7: =1/(1+C13)^0.5 -> 0.95570192 | D7: =1/(1+C13)^1.5 -> 0.8729058 | E7: =1/(1+C13)^2.5 -> 0.79728263 | F7: =1/(1+C13)^3.5 -> 0.72821098 | G7: =1/(1+C13)^4.5 -> 0.66512327 | H7: Standard discounting, 1/(1+WACC)^1, assumes each year's FCF arrives on the last day of the year.
B8: PV of FCF | C8: =C6*C7 -> 33997.782 | D8: =D6*D7 -> 59598.332 | E8: =E6*E7 -> 76845.639 | F8: =F6*F7 -> 90852.776 | G8: =G6*G7 -> 100078.23 | H8: Mid year convention, 1/(1+WACC)^(0.5), is applied to approximate the PV at the midpoint of the year
B10: TERMINAL VALUE (Gordon Growth Method)
B11: Final Year FCF | C11: =G6 -> 150465.68
B12: Terminal Growth Rate | C12: 0.04 | D12: Nominal GDP Growth = Real GDP Growth + PCE Inflation
B13: WACC | C13: 0.094851151 | D13: Linked from 'WACC'
B14: Terminal Value (at end of Year 5) | C14: =C11*(1+C12)/(C13-C12) -> 2852890.1
B15: PV of Terminal Value | C15: =C14*G7 -> 1897523.6
B17: ENTERPRISE VALUE | C17: =SUM(C8:G8)+C15 -> 2258896.4 | D17: Total PV of FCF + PV of Terminal Value
B18: Less: Net Debt | C18: =-(WACC!C8+WACC!D8-20935) -> -82159 | D18: Net Debt = MV of Debt in 'WACC' + MV of Finance Leases in 'WACC' - Cash & Cash Equivalents (10-K Balance sheet)
B19: EQUITY VALUE | C19: =C17+C18 -> 2176737.4
B20: Shares Outstanding (mm) | C20: =7427000000/1000000 -> 7427 | D20: Linked from 'WACC'
B21: IMPLIED SHARE PRICE | C21: =IF(C20=0,0,C19/C20) -> 293.08434
B24: SENSITIVITY ON IMPLIED SHARE PRICE
B25: =C21 -> 293.08434
B26: WACC \ Terminal Growth | C26: 0.03 | D26: 0.035 | E26: 0.04 | F26: 0.045 | G26: 0.05
B27: 0.074851151 | C27: 376.54825 | D27: 420.5693 | E27: 477.22151 | F27: 552.85196 | G27: 658.91579
B28: 0.084851151 | C28: 302.63383 | D28: 330.49104 | E28: 364.55928 | F28: 407.17639 | G28: 462.02183
B29: 0.094851151 | C29: 251.61016 | D29: 270.61486 | E29: 293.08434 | F29: 320.06113 | G29: 353.05266
B30: 0.10485115 | C30: 214.29915 | D30: 227.9657 | E30: 243.73962 | F30: 262.14906 | G30: 283.91475
B31: 0.11485115 | C31: 185.84959 | D31: 196.0683 | E31: 207.65221 | F31: 220.89449 | G31: 236.17873
